<?xml version="1.0" encoding="utf-8"?>
<!-- This URDF was automatically created by SolidWorks to URDF Exporter! Originally created by Stephen Brawner (brawner@gmail.com) 
     Commit Version: 1.6.0-4-g7f85cfe  Build Version: 1.6.7995.38578
     For more information, please see http://wiki.ros.org/sw_urdf_exporter -->
<robot
  name="cartesian_robot">
  <link
    name="base_link">
    <inertial>
      <origin
        xyz="0.29184 0.032677 -0.15851"
        rpy="0 0 0" />
      <mass
        value="0.25637" />
      <inertia
        ixx="9.8383E-05"
        ixy="-1.7674E-09"
        ixz="-1.4664E-07"
        iyy="9.8335E-05"
        iyz="-7.7226E-08"
        izz="8.3997E-05" />
    </inertial>
    <visual>
      <origin
        xyz="0 0 0"
        rpy="0 0 0" />
      <geometry>
        <mesh
          filename="package://arm_description/meshes/base_link.STL" />
      </geometry>
      <material
        name="">
        <color
          rgba="1 0.94902 0.89412 1" />
      </material>
    </visual>
    <collision>
      <origin
        xyz="0 0 0"
        rpy="0 0 0" />
      <geometry>
        <mesh
          filename="package://arm_description/meshes/base_link.STL" />
      </geometry>
    </collision>
  </link>
  <link
    name="additioanal_base_link">
    <inertial>
      <origin
        xyz="0.11761 0.05645 0.024045"
        rpy="0 0 0" />
      <mass
        value="4.4856" />
      <inertia
        ixx="0.027725"
        ixy="3.727E-05"
        ixz="-4.7376E-08"
        iyy="0.0019325"
        iyz="1.6485E-06"
        izz="0.027745" />
    </inertial>
    <visual>
      <origin
        xyz="0 0 0"
        rpy="0 0 0" />
      <geometry>
        <mesh
          filename="package://arm_description/meshes/additioanal_base_link.STL" />
      </geometry>
      <material
        name="">
        <color
          rgba="1 0.94902 0.89412 1" />
      </material>
    </visual>
    <collision>
      <origin
        xyz="0 0 0"
        rpy="0 0 0" />
      <geometry>
        <mesh
          filename="package://arm_description/meshes/additioanal_base_link.STL" />
      </geometry>
    </collision>
  </link>
  <joint
    name="joint1"
    type="fixed">
    <origin
      xyz="0.1741 0.18232 0.095474"
      rpy="1.5708 0.0036853 0" />
    <parent
      link="base_link" />
    <child
      link="additioanal_base_link" />
    <axis
      xyz="0 0 0" />
  </joint>
  <link
    name="x_rail_Link">
    <inertial>
      <origin
        xyz="0.40747 -0.014382 -0.0037531"
        rpy="0 0 0" />
      <mass
        value="2.0718" />
      <inertia
        ixx="0.00057526"
        ixy="3.4537E-07"
        ixz="4.3606E-08"
        iyy="0.02035"
        iyz="-1.5331E-10"
        izz="0.020084" />
    </inertial>
    <visual>
      <origin
        xyz="0 0 0"
        rpy="0 0 0" />
      <geometry>
        <mesh
          filename="package://arm_description/meshes/x_rail_Link.STL" />
      </geometry>
      <material
        name="">
        <color
          rgba="1 0.94902 0.89412 1" />
      </material>
    </visual>
    <collision>
      <origin
        xyz="0 0 0"
        rpy="0 0 0" />
      <geometry>
        <mesh
          filename="package://arm_description/meshes/x_rail_Link.STL" />
      </geometry>
    </collision>
  </link>
  <joint
    name="joint2"
    type="fixed">
    <origin
      xyz="-0.27738 0.17813 0.021237"
      rpy="3.1416 0 0" />
    <parent
      link="additioanal_base_link" />
    <child
      link="x_rail_Link" />
    <axis
      xyz="0 0 0" />
  </joint>
  <link
    name="x_Link">
    <inertial>
      <origin
        xyz="0.4338 -0.0037341 -0.028595"
        rpy="0 0 0" />
      <mass
        value="1.6493" />
      <inertia
        ixx="0.0004869"
        ixy="1.3349E-06"
        ixz="2.5093E-05"
        iyy="0.0081592"
        iyz="3.3416E-06"
        izz="0.0083426" />
    </inertial>
    <visual>
      <origin
        xyz="0 0 0"
        rpy="0 0 0" />
      <geometry>
        <mesh
          filename="package://arm_description/meshes/x_Link.STL" />
      </geometry>
      <material
        name="">
        <color
          rgba="1 0.94902 0.89412 1" />
      </material>
    </visual>
    <collision>
      <origin
        xyz="0 0 0"
        rpy="0 0 0" />
      <geometry>
        <mesh
          filename="package://arm_description/meshes/x_Link.STL" />
      </geometry>
    </collision>
  </link>
  <joint
    name="joint3"
    type="prismatic">
    <origin
      xyz="0.37179 -0.067263 0.32241"
      rpy="0 1.5708 3.1416" />
    <parent
      link="x_rail_Link" />
    <child
      link="x_Link" />
    <axis
      xyz="0 0 1" />
    <limit
      lower="-0.125"
      upper="0.120"
      effort="1000.0"
      velocity="0.1" />
  </joint>
  <link
    name="y_Link">
    <inertial>
      <origin
        xyz="0.02158 0.025607 -0.012113"
        rpy="0 0 0" />
      <mass
        value="0.57113" />
      <inertia
        ixx="0.0017342"
        ixy="-6.3684E-07"
        ixz="1.5847E-07"
        iyy="5.4819E-05"
        iyz="-1.0238E-06"
        izz="0.0017323" />
    </inertial>
    <visual>
      <origin
        xyz="0 0 0"
        rpy="0 0 0" />
      <geometry>
        <mesh
          filename="package://arm_description/meshes/y_Link.STL" />
      </geometry>
      <material
        name="">
        <color
          rgba="1 0.94902 0.89412 1" />
      </material>
    </visual>
    <collision>
      <origin
        xyz="0 0 0"
        rpy="0 0 0" />
      <geometry>
        <mesh
          filename="package://arm_description/meshes/y_Link.STL" />
      </geometry>
    </collision>
  </link>
  <joint
    name="joint4"
    type="prismatic">
    <origin
      xyz="0.40246 0.019644 -0.0080109"
      rpy="3.1416 0 0" />
    <parent
      link="x_Link" />
    <child
      link="y_Link" />
    <axis
      xyz="1 0 0" />
    <limit
      lower="-0.051"
      upper="0.118"
      effort="1000.0"
      velocity="0.1" />
  </joint>
  <link
    name="z_Link">
    <inertial>
      <origin
        xyz="-0.032527 0.012162 0.0075268"
        rpy="0 0 0" />
      <mass
        value="0.071692" />
      <inertia
        ixx="2.3649E-05"
        ixy="-4.7082E-10"
        ixz="2.0327E-08"
        iyy="3.6289E-05"
        iyz="1.6593E-09"
        izz="1.8063E-05" />
    </inertial>
    <visual>
      <origin
        xyz="0 0 0"
        rpy="0 0 0" />
      <geometry>
        <mesh
          filename="package://arm_description/meshes/z_Link.STL" />
      </geometry>
      <material
        name="">
        <color
          rgba="0.79216 0.81961 0.93333 1" />
      </material>
    </visual>
    <collision>
      <origin
        xyz="0 0 0"
        rpy="0 0 0" />
      <geometry>
        <mesh
          filename="package://arm_description/meshes/z_Link.STL" />
      </geometry>
    </collision>
  </link>
  <joint
    name="joint5"
    type="prismatic">
    <origin
      xyz="0.009476 0.067985 -0.070619"
      rpy="0 0 -1.5708" />
    <parent
      link="y_Link" />
    <child
      link="z_Link" />
    <axis
      xyz="1 0 0" />
    <limit
      lower="-0.054"
      upper="0.115"
      effort="1000.0"
      velocity="0.1" />
  </joint>
<transmission name="x_trans">
  <plugin>transmission_interface/SimpleTransmission</plugin>
  <joint name="joint3">
    <hardwareInterface>hardware_interface/PositionJointInterface</hardwareInterface>
  </joint>
  <actuator name="x_motor">
    <mechanicalReduction>1</mechanicalReduction>
  </actuator>
</transmission>

<transmission name="y_trans">
  <plugin>transmission_interface/SimpleTransmission</plugin>
  <joint name="joint4">
    <hardwareInterface>hardware_interface/PositionJointInterface</hardwareInterface>
  </joint>
  <actuator name="y_motor">
    <mechanicalReduction>1</mechanicalReduction>
  </actuator>
</transmission>

<transmission name="z_trans">
  <plugin>transmission_interface/SimpleTransmission</plugin>
  <joint name="joint5">
    <hardwareInterface>hardware_interface/PositionJointInterface</hardwareInterface>
  </joint>
  <actuator name="z_motor">
    <mechanicalReduction>1</mechanicalReduction>
  </actuator>
</transmission>

<gazebo>
  <plugin name="gazebo_ros2_control" filename="libgazebo_ros2_control.so">
    <robot_param>robot_description</robot_param>
    <robot_param_node>robot_state_publisher</robot_param_node>
    <parameters>$(find arm_controller)/config/controllers.yaml</parameters>
  </plugin>
</gazebo>

<ros2_control name="RobotSystem" type="system">
  <hardware>
    <plugin>gazebo_ros2_control/GazeboSystem</plugin>
  </hardware>

  <joint name="joint3">
    <command_interface name="position">
      <param name="min">-0.125</param>
      <param name="max">0.120</param>
    </command_interface>
    <state_interface name="position"/>
  </joint>

  <joint name="joint4">
    <command_interface name="position">
      <param name="min">-0.051</param>
      <param name="max">0.118</param>
    </command_interface>
    <state_interface name="position"/>
  </joint>

  <joint name="joint5">
    <command_interface name="position">
      <param name="min">-0.054</param>
      <param name="max">0.115</param>
    </command_interface>
    <state_interface name="position"/>
  </joint>
</ros2_control>

</robot>
